2024-03-13 18:20:45 - WARNING - PyNaCl is not installed, voice will NOT be supported
2024-03-13 18:20:45 - INFO - logging in using static token
2024-03-13 18:20:45 - INFO - Shard ID None has connected to Gateway (Session ID: fca067a4a1bcb1d1af5b8cb2281e981a).
2024-03-13 18:20:47 - INFO - Bot has started and is ready.
2024-03-13 18:28:32 - WARNING - PyNaCl is not installed, voice will NOT be supported
2024-03-13 18:28:32 - INFO - logging in using static token
2024-03-13 18:28:33 - INFO - Shard ID None has connected to Gateway (Session ID: 5e9383a3e19c5f6182c09c7122c7eca0).
2024-03-13 18:28:35 - INFO - Bot has started and is ready.
2024-03-13 18:28:51 - INFO - itzkagyu requested for hello
2024-03-13 18:29:02 - INFO - 8Ball used by itzkagyu, sendtSigns point to yes. .
2024-03-13 18:29:34 - WARNING - PyNaCl is not installed, voice will NOT be supported
2024-03-13 18:29:34 - INFO - logging in using static token
2024-03-13 18:29:35 - INFO - Shard ID None has connected to Gateway (Session ID: c4023e10a5f26a7e0b6cb121264b5a85).
2024-03-13 18:29:37 - INFO - Bot has started and is ready.
2024-03-13 18:32:46 - INFO - logging in using static token
2024-03-13 18:32:47 - INFO - Shard ID None has connected to Gateway (Session ID: 27c7863ac51e0066c34948f62d1653af).
2024-03-13 18:32:49 - INFO - Bot has started and is ready.
2024-03-13 18:32:57 - INFO - Connecting to voice...
2024-03-13 18:32:57 - INFO - Starting voice handshake... (connection attempt 1)
2024-03-13 18:32:57 - INFO - Voice handshake complete. Endpoint found us-central9229.discord.media
2024-03-13 18:33:40 - ERROR - Ignoring exception in command play
Traceback (most recent call last):
  File "c:\Users\isaac\AppData\Local\Programs\Python\Python310\lib\site-packages\discord\ext\commands\bot.py", line 1350, in invoke
    await ctx.command.invoke(ctx)
  File "c:\Users\isaac\AppData\Local\Programs\Python\Python310\lib\site-packages\discord\ext\commands\core.py", line 1021, in invoke
    await self.prepare(ctx)
  File "c:\Users\isaac\AppData\Local\Programs\Python\Python310\lib\site-packages\discord\ext\commands\core.py", line 938, in prepare
    await self._parse_arguments(ctx)
  File "c:\Users\isaac\AppData\Local\Programs\Python\Python310\lib\site-packages\discord\ext\commands\core.py", line 853, in _parse_arguments
    kwargs[name] = await self.transform(ctx, param, attachments)
  File "c:\Users\isaac\AppData\Local\Programs\Python\Python310\lib\site-packages\discord\ext\commands\core.py", line 697, in transform
    raise MissingRequiredArgument(param)
discord.ext.commands.errors.MissingRequiredArgument: url is a required argument that is missing.
2024-03-13 18:33:46 - ERROR - Ignoring exception in command play
Traceback (most recent call last):
  File "c:\Users\isaac\AppData\Local\Programs\Python\Python310\lib\site-packages\youtube_dl\YoutubeDL.py", line 815, in wrapper
    return func(self, *args, **kwargs)
  File "c:\Users\isaac\AppData\Local\Programs\Python\Python310\lib\site-packages\youtube_dl\YoutubeDL.py", line 836, in __extract_info
    ie_result = ie.extract(url)
  File "c:\Users\isaac\AppData\Local\Programs\Python\Python310\lib\site-packages\youtube_dl\extractor\common.py", line 534, in extract
    ie_result = self._real_extract(url)
  File "c:\Users\isaac\AppData\Local\Programs\Python\Python310\lib\site-packages\youtube_dl\extractor\youtube.py", line 1794, in _real_extract
    'uploader_id': self._search_regex(r'/(?:channel|user)/([^/?&#]+)', owner_profile_url, 'uploader id') if owner_profile_url else None,
  File "c:\Users\isaac\AppData\Local\Programs\Python\Python310\lib\site-packages\youtube_dl\extractor\common.py", line 1012, in _search_regex
    raise RegexNotFoundError('Unable to extract %s' % _name)
youtube_dl.utils.RegexNotFoundError: Unable to extract uploader id

During handling of the above exception, another exception occurred:

Traceback (most recent call last):
  File "c:\Users\isaac\AppData\Local\Programs\Python\Python310\lib\site-packages\discord\ext\commands\core.py", line 235, in wrapped
    ret = await coro(*args, **kwargs)
  File "c:\Users\isaac\Documents\My Projects\SeShack\myBot.py", line 417, in play
    player = await YTDLSource.from_url(url, loop=bot.loop)
  File "c:\Users\isaac\Documents\My Projects\SeShack\myBot.py", line 110, in from_url
    data = await loop.run_in_executor(None, lambda: ytdl.extract_info(url, download=not stream))
  File "c:\Users\isaac\AppData\Local\Programs\Python\Python310\lib\concurrent\futures\thread.py", line 58, in run
    result = self.fn(*self.args, **self.kwargs)
  File "c:\Users\isaac\Documents\My Projects\SeShack\myBot.py", line 110, in <lambda>
    data = await loop.run_in_executor(None, lambda: ytdl.extract_info(url, download=not stream))
  File "c:\Users\isaac\AppData\Local\Programs\Python\Python310\lib\site-packages\youtube_dl\YoutubeDL.py", line 808, in extract_info
    return self.__extract_info(url, ie, download, extra_info, process)
  File "c:\Users\isaac\AppData\Local\Programs\Python\Python310\lib\site-packages\youtube_dl\YoutubeDL.py", line 824, in wrapper
    self.report_error(compat_str(e), e.format_traceback())
  File "c:\Users\isaac\AppData\Local\Programs\Python\Python310\lib\site-packages\youtube_dl\YoutubeDL.py", line 628, in report_error
    self.trouble(error_message, tb)
  File "c:\Users\isaac\AppData\Local\Programs\Python\Python310\lib\site-packages\youtube_dl\YoutubeDL.py", line 598, in trouble
    raise DownloadError(message, exc_info)
youtube_dl.utils.DownloadError: ERROR: Unable to extract uploader id

The above exception was the direct cause of the following exception:

Traceback (most recent call last):
  File "c:\Users\isaac\AppData\Local\Programs\Python\Python310\lib\site-packages\discord\ext\commands\bot.py", line 1350, in invoke
    await ctx.command.invoke(ctx)
  File "c:\Users\isaac\AppData\Local\Programs\Python\Python310\lib\site-packages\discord\ext\commands\core.py", line 1029, in invoke
    await injected(*ctx.args, **ctx.kwargs)  # type: ignore
  File "c:\Users\isaac\AppData\Local\Programs\Python\Python310\lib\site-packages\discord\ext\commands\core.py", line 244, in wrapped
    raise CommandInvokeError(exc) from exc
discord.ext.commands.errors.CommandInvokeError: Command raised an exception: DownloadError: ERROR: Unable to extract uploader id
2024-03-13 18:34:12 - INFO - logging in using static token
2024-03-13 18:34:13 - INFO - Shard ID None has connected to Gateway (Session ID: e17eeec4002564cdc2cf6b9beb925fc7).
2024-03-13 18:34:15 - INFO - Bot has started and is ready.
2024-03-13 18:34:23 - ERROR - Ignoring exception in command leave
Traceback (most recent call last):
  File "c:\Users\isaac\AppData\Local\Programs\Python\Python310\lib\site-packages\discord\ext\commands\core.py", line 235, in wrapped
    ret = await coro(*args, **kwargs)
  File "c:\Users\isaac\Documents\My Projects\SeShack\myBot.py", line 433, in leave
    await ctx.voice_client.disconnect()
AttributeError: 'NoneType' object has no attribute 'disconnect'

The above exception was the direct cause of the following exception:

Traceback (most recent call last):
  File "c:\Users\isaac\AppData\Local\Programs\Python\Python310\lib\site-packages\discord\ext\commands\bot.py", line 1350, in invoke
    await ctx.command.invoke(ctx)
  File "c:\Users\isaac\AppData\Local\Programs\Python\Python310\lib\site-packages\discord\ext\commands\core.py", line 1029, in invoke
    await injected(*ctx.args, **ctx.kwargs)  # type: ignore
  File "c:\Users\isaac\AppData\Local\Programs\Python\Python310\lib\site-packages\discord\ext\commands\core.py", line 244, in wrapped
    raise CommandInvokeError(exc) from exc
discord.ext.commands.errors.CommandInvokeError: Command raised an exception: AttributeError: 'NoneType' object has no attribute 'disconnect'
2024-03-13 18:35:10 - INFO - logging in using static token
2024-03-13 18:35:11 - INFO - Shard ID None has connected to Gateway (Session ID: 08e510e4849cce1b6673d06081032ce7).
2024-03-13 18:35:13 - INFO - Bot has started and is ready.
2024-03-13 18:35:16 - INFO - Connecting to voice...
2024-03-13 18:35:16 - INFO - Starting voice handshake... (connection attempt 1)
2024-03-13 18:35:16 - INFO - Voice handshake complete. Endpoint found us-central9229.discord.media
2024-03-13 18:35:29 - ERROR - Ignoring exception in command play
Traceback (most recent call last):
  File "c:\Users\isaac\AppData\Local\Programs\Python\Python310\lib\site-packages\youtube_dl\YoutubeDL.py", line 815, in wrapper
    return func(self, *args, **kwargs)
  File "c:\Users\isaac\AppData\Local\Programs\Python\Python310\lib\site-packages\youtube_dl\YoutubeDL.py", line 836, in __extract_info
    ie_result = ie.extract(url)
  File "c:\Users\isaac\AppData\Local\Programs\Python\Python310\lib\site-packages\youtube_dl\extractor\common.py", line 534, in extract
    ie_result = self._real_extract(url)
  File "c:\Users\isaac\AppData\Local\Programs\Python\Python310\lib\site-packages\youtube_dl\extractor\youtube.py", line 1794, in _real_extract
    'uploader_id': self._search_regex(r'/(?:channel|user)/([^/?&#]+)', owner_profile_url, 'uploader id') if owner_profile_url else None,
  File "c:\Users\isaac\AppData\Local\Programs\Python\Python310\lib\site-packages\youtube_dl\extractor\common.py", line 1012, in _search_regex
    raise RegexNotFoundError('Unable to extract %s' % _name)
youtube_dl.utils.RegexNotFoundError: Unable to extract uploader id

During handling of the above exception, another exception occurred:

Traceback (most recent call last):
  File "c:\Users\isaac\AppData\Local\Programs\Python\Python310\lib\site-packages\discord\ext\commands\core.py", line 235, in wrapped
    ret = await coro(*args, **kwargs)
  File "c:\Users\isaac\Documents\My Projects\SeShack\myBot.py", line 417, in play
    player = await YTDLSource.from_url(url, loop=bot.loop)
  File "c:\Users\isaac\Documents\My Projects\SeShack\myBot.py", line 110, in from_url
    data = await loop.run_in_executor(None, lambda: ytdl.extract_info(url, download=not stream))
  File "c:\Users\isaac\AppData\Local\Programs\Python\Python310\lib\concurrent\futures\thread.py", line 58, in run
    result = self.fn(*self.args, **self.kwargs)
  File "c:\Users\isaac\Documents\My Projects\SeShack\myBot.py", line 110, in <lambda>
    data = await loop.run_in_executor(None, lambda: ytdl.extract_info(url, download=not stream))
  File "c:\Users\isaac\AppData\Local\Programs\Python\Python310\lib\site-packages\youtube_dl\YoutubeDL.py", line 808, in extract_info
    return self.__extract_info(url, ie, download, extra_info, process)
  File "c:\Users\isaac\AppData\Local\Programs\Python\Python310\lib\site-packages\youtube_dl\YoutubeDL.py", line 824, in wrapper
    self.report_error(compat_str(e), e.format_traceback())
  File "c:\Users\isaac\AppData\Local\Programs\Python\Python310\lib\site-packages\youtube_dl\YoutubeDL.py", line 628, in report_error
    self.trouble(error_message, tb)
  File "c:\Users\isaac\AppData\Local\Programs\Python\Python310\lib\site-packages\youtube_dl\YoutubeDL.py", line 598, in trouble
    raise DownloadError(message, exc_info)
youtube_dl.utils.DownloadError: ERROR: Unable to extract uploader id

The above exception was the direct cause of the following exception:

Traceback (most recent call last):
  File "c:\Users\isaac\AppData\Local\Programs\Python\Python310\lib\site-packages\discord\ext\commands\bot.py", line 1350, in invoke
    await ctx.command.invoke(ctx)
  File "c:\Users\isaac\AppData\Local\Programs\Python\Python310\lib\site-packages\discord\ext\commands\core.py", line 1029, in invoke
    await injected(*ctx.args, **ctx.kwargs)  # type: ignore
  File "c:\Users\isaac\AppData\Local\Programs\Python\Python310\lib\site-packages\discord\ext\commands\core.py", line 244, in wrapped
    raise CommandInvokeError(exc) from exc
discord.ext.commands.errors.CommandInvokeError: Command raised an exception: DownloadError: ERROR: Unable to extract uploader id
2024-03-13 18:35:52 - INFO - Disconnecting from voice normally, close code 1000.
2024-03-13 18:35:52 - INFO - The voice handshake is being terminated for Channel ID 1046467680003174443 (Guild ID 1046467676215726172)
2024-03-13 18:36:50 - INFO - logging in using static token
2024-03-13 18:36:51 - INFO - Shard ID None has connected to Gateway (Session ID: f08c6da88ed80307a00dd5a33d10560f).
2024-03-13 18:36:53 - INFO - Bot has started and is ready.
2024-03-13 18:36:54 - ERROR - Ignoring exception in command play
Traceback (most recent call last):
  File "c:\Users\isaac\AppData\Local\Programs\Python\Python310\lib\site-packages\discord\ext\commands\bot.py", line 1350, in invoke
    await ctx.command.invoke(ctx)
  File "c:\Users\isaac\AppData\Local\Programs\Python\Python310\lib\site-packages\discord\ext\commands\core.py", line 1021, in invoke
    await self.prepare(ctx)
  File "c:\Users\isaac\AppData\Local\Programs\Python\Python310\lib\site-packages\discord\ext\commands\core.py", line 938, in prepare
    await self._parse_arguments(ctx)
  File "c:\Users\isaac\AppData\Local\Programs\Python\Python310\lib\site-packages\discord\ext\commands\core.py", line 853, in _parse_arguments
    kwargs[name] = await self.transform(ctx, param, attachments)
  File "c:\Users\isaac\AppData\Local\Programs\Python\Python310\lib\site-packages\discord\ext\commands\core.py", line 697, in transform
    raise MissingRequiredArgument(param)
discord.ext.commands.errors.MissingRequiredArgument: url is a required argument that is missing.
2024-03-13 18:36:59 - INFO - Connecting to voice...
2024-03-13 18:36:59 - INFO - Starting voice handshake... (connection attempt 1)
2024-03-13 18:36:59 - INFO - Voice handshake complete. Endpoint found us-central9229.discord.media
2024-03-13 18:37:09 - ERROR - Ignoring exception in command play
Traceback (most recent call last):
  File "c:\Users\isaac\AppData\Local\Programs\Python\Python310\lib\site-packages\yt_dlp\YoutubeDL.py", line 3512, in process_info
    replace_info_dict(self.post_process(dl_filename, info_dict, files_to_move))
  File "c:\Users\isaac\AppData\Local\Programs\Python\Python310\lib\site-packages\yt_dlp\YoutubeDL.py", line 3694, in post_process
    info = self.run_all_pps('post_process', info, additional_pps=info.get('__postprocessors'))
  File "c:\Users\isaac\AppData\Local\Programs\Python\Python310\lib\site-packages\yt_dlp\YoutubeDL.py", line 3676, in run_all_pps
    info = self.run_pp(pp, info)
  File "c:\Users\isaac\AppData\Local\Programs\Python\Python310\lib\site-packages\yt_dlp\YoutubeDL.py", line 3654, in run_pp
    files_to_delete, infodict = pp.run(infodict)
  File "c:\Users\isaac\AppData\Local\Programs\Python\Python310\lib\site-packages\yt_dlp\postprocessor\common.py", line 23, in run
    ret = func(self, info, *args, **kwargs)
  File "c:\Users\isaac\AppData\Local\Programs\Python\Python310\lib\site-packages\yt_dlp\postprocessor\common.py", line 128, in wrapper
    return func(self, info)
  File "c:\Users\isaac\AppData\Local\Programs\Python\Python310\lib\site-packages\yt_dlp\postprocessor\ffmpeg.py", line 493, in run
    filecodec = self.get_audio_codec(path)
  File "c:\Users\isaac\AppData\Local\Programs\Python\Python310\lib\site-packages\yt_dlp\postprocessor\ffmpeg.py", line 241, in get_audio_codec
    raise PostProcessingError('ffprobe and ffmpeg not found. Please install or provide the path using --ffmpeg-location')
yt_dlp.utils.PostProcessingError: ffprobe and ffmpeg not found. Please install or provide the path using --ffmpeg-location

During handling of the above exception, another exception occurred:

Traceback (most recent call last):
  File "c:\Users\isaac\AppData\Local\Programs\Python\Python310\lib\site-packages\discord\ext\commands\core.py", line 235, in wrapped
    ret = await coro(*args, **kwargs)
  File "c:\Users\isaac\Documents\My Projects\SeShack\myBot.py", line 417, in play
    player = await YTDLSource.from_url(url, loop=bot.loop)
  File "c:\Users\isaac\Documents\My Projects\SeShack\myBot.py", line 110, in from_url
    data = await loop.run_in_executor(None, lambda: ytdl.extract_info(url, download=not stream))
  File "c:\Users\isaac\AppData\Local\Programs\Python\Python310\lib\concurrent\futures\thread.py", line 58, in run
    result = self.fn(*self.args, **self.kwargs)
  File "c:\Users\isaac\Documents\My Projects\SeShack\myBot.py", line 110, in <lambda>
    data = await loop.run_in_executor(None, lambda: ytdl.extract_info(url, download=not stream))
  File "c:\Users\isaac\AppData\Local\Programs\Python\Python310\lib\site-packages\yt_dlp\YoutubeDL.py", line 1583, in extract_info
    return self.__extract_info(url, self.get_info_extractor(key), download, extra_info, process)
  File "c:\Users\isaac\AppData\Local\Programs\Python\Python310\lib\site-packages\yt_dlp\YoutubeDL.py", line 1594, in wrapper
    return func(self, *args, **kwargs)
  File "c:\Users\isaac\AppData\Local\Programs\Python\Python310\lib\site-packages\yt_dlp\YoutubeDL.py", line 1750, in __extract_info
    return self.process_ie_result(ie_result, download, extra_info)
  File "c:\Users\isaac\AppData\Local\Programs\Python\Python310\lib\site-packages\yt_dlp\YoutubeDL.py", line 1809, in process_ie_result
    ie_result = self.process_video_result(ie_result, download=download)
  File "c:\Users\isaac\AppData\Local\Programs\Python\Python310\lib\site-packages\yt_dlp\YoutubeDL.py", line 2968, in process_video_result
    self.process_info(new_info)
  File "c:\Users\isaac\AppData\Local\Programs\Python\Python310\lib\site-packages\yt_dlp\YoutubeDL.py", line 3514, in process_info
    self.report_error('Postprocessing: %s' % str(err))
  File "c:\Users\isaac\AppData\Local\Programs\Python\Python310\lib\site-packages\yt_dlp\YoutubeDL.py", line 1061, in report_error
    self.trouble(f'{self._format_err("ERROR:", self.Styles.ERROR)} {message}', *args, **kwargs)
  File "c:\Users\isaac\AppData\Local\Programs\Python\Python310\lib\site-packages\yt_dlp\YoutubeDL.py", line 1000, in trouble
    raise DownloadError(message, exc_info)
yt_dlp.utils.DownloadError: [0;31mERROR:[0m Postprocessing: ffprobe and ffmpeg not found. Please install or provide the path using --ffmpeg-location

The above exception was the direct cause of the following exception:

Traceback (most recent call last):
  File "c:\Users\isaac\AppData\Local\Programs\Python\Python310\lib\site-packages\discord\ext\commands\bot.py", line 1350, in invoke
    await ctx.command.invoke(ctx)
  File "c:\Users\isaac\AppData\Local\Programs\Python\Python310\lib\site-packages\discord\ext\commands\core.py", line 1029, in invoke
    await injected(*ctx.args, **ctx.kwargs)  # type: ignore
  File "c:\Users\isaac\AppData\Local\Programs\Python\Python310\lib\site-packages\discord\ext\commands\core.py", line 244, in wrapped
    raise CommandInvokeError(exc) from exc
discord.ext.commands.errors.CommandInvokeError: Command raised an exception: DownloadError: [0;31mERROR:[0m Postprocessing: ffprobe and ffmpeg not found. Please install or provide the path using --ffmpeg-location
2024-03-13 18:38:10 - INFO - Connecting to voice...
2024-03-13 18:38:10 - INFO - Starting voice handshake... (connection attempt 1)
2024-03-13 18:38:10 - INFO - Voice handshake complete. Endpoint found us-central4183.discord.media
2024-03-13 18:38:25 - ERROR - Ignoring exception in command play
Traceback (most recent call last):
  File "c:\Users\isaac\AppData\Local\Programs\Python\Python310\lib\site-packages\yt_dlp\YoutubeDL.py", line 3512, in process_info
    replace_info_dict(self.post_process(dl_filename, info_dict, files_to_move))
  File "c:\Users\isaac\AppData\Local\Programs\Python\Python310\lib\site-packages\yt_dlp\YoutubeDL.py", line 3694, in post_process
    info = self.run_all_pps('post_process', info, additional_pps=info.get('__postprocessors'))
  File "c:\Users\isaac\AppData\Local\Programs\Python\Python310\lib\site-packages\yt_dlp\YoutubeDL.py", line 3676, in run_all_pps
    info = self.run_pp(pp, info)
  File "c:\Users\isaac\AppData\Local\Programs\Python\Python310\lib\site-packages\yt_dlp\YoutubeDL.py", line 3654, in run_pp
    files_to_delete, infodict = pp.run(infodict)
  File "c:\Users\isaac\AppData\Local\Programs\Python\Python310\lib\site-packages\yt_dlp\postprocessor\common.py", line 23, in run
    ret = func(self, info, *args, **kwargs)
  File "c:\Users\isaac\AppData\Local\Programs\Python\Python310\lib\site-packages\yt_dlp\postprocessor\common.py", line 128, in wrapper
    return func(self, info)
  File "c:\Users\isaac\AppData\Local\Programs\Python\Python310\lib\site-packages\yt_dlp\postprocessor\ffmpeg.py", line 493, in run
    filecodec = self.get_audio_codec(path)
  File "c:\Users\isaac\AppData\Local\Programs\Python\Python310\lib\site-packages\yt_dlp\postprocessor\ffmpeg.py", line 241, in get_audio_codec
    raise PostProcessingError('ffprobe and ffmpeg not found. Please install or provide the path using --ffmpeg-location')
yt_dlp.utils.PostProcessingError: ffprobe and ffmpeg not found. Please install or provide the path using --ffmpeg-location

During handling of the above exception, another exception occurred:

Traceback (most recent call last):
  File "c:\Users\isaac\AppData\Local\Programs\Python\Python310\lib\site-packages\discord\ext\commands\core.py", line 235, in wrapped
    ret = await coro(*args, **kwargs)
  File "c:\Users\isaac\Documents\My Projects\SeShack\myBot.py", line 417, in play
    player = await YTDLSource.from_url(url, loop=bot.loop)
  File "c:\Users\isaac\Documents\My Projects\SeShack\myBot.py", line 110, in from_url
    data = await loop.run_in_executor(None, lambda: ytdl.extract_info(url, download=not stream))
  File "c:\Users\isaac\AppData\Local\Programs\Python\Python310\lib\concurrent\futures\thread.py", line 58, in run
    result = self.fn(*self.args, **self.kwargs)
  File "c:\Users\isaac\Documents\My Projects\SeShack\myBot.py", line 110, in <lambda>
    data = await loop.run_in_executor(None, lambda: ytdl.extract_info(url, download=not stream))
  File "c:\Users\isaac\AppData\Local\Programs\Python\Python310\lib\site-packages\yt_dlp\YoutubeDL.py", line 1583, in extract_info
    return self.__extract_info(url, self.get_info_extractor(key), download, extra_info, process)
  File "c:\Users\isaac\AppData\Local\Programs\Python\Python310\lib\site-packages\yt_dlp\YoutubeDL.py", line 1594, in wrapper
    return func(self, *args, **kwargs)
  File "c:\Users\isaac\AppData\Local\Programs\Python\Python310\lib\site-packages\yt_dlp\YoutubeDL.py", line 1750, in __extract_info
    return self.process_ie_result(ie_result, download, extra_info)
  File "c:\Users\isaac\AppData\Local\Programs\Python\Python310\lib\site-packages\yt_dlp\YoutubeDL.py", line 1809, in process_ie_result
    ie_result = self.process_video_result(ie_result, download=download)
  File "c:\Users\isaac\AppData\Local\Programs\Python\Python310\lib\site-packages\yt_dlp\YoutubeDL.py", line 2968, in process_video_result
    self.process_info(new_info)
  File "c:\Users\isaac\AppData\Local\Programs\Python\Python310\lib\site-packages\yt_dlp\YoutubeDL.py", line 3514, in process_info
    self.report_error('Postprocessing: %s' % str(err))
  File "c:\Users\isaac\AppData\Local\Programs\Python\Python310\lib\site-packages\yt_dlp\YoutubeDL.py", line 1061, in report_error
    self.trouble(f'{self._format_err("ERROR:", self.Styles.ERROR)} {message}', *args, **kwargs)
  File "c:\Users\isaac\AppData\Local\Programs\Python\Python310\lib\site-packages\yt_dlp\YoutubeDL.py", line 1000, in trouble
    raise DownloadError(message, exc_info)
yt_dlp.utils.DownloadError: [0;31mERROR:[0m Postprocessing: ffprobe and ffmpeg not found. Please install or provide the path using --ffmpeg-location

The above exception was the direct cause of the following exception:

Traceback (most recent call last):
  File "c:\Users\isaac\AppData\Local\Programs\Python\Python310\lib\site-packages\discord\ext\commands\bot.py", line 1350, in invoke
    await ctx.command.invoke(ctx)
  File "c:\Users\isaac\AppData\Local\Programs\Python\Python310\lib\site-packages\discord\ext\commands\core.py", line 1029, in invoke
    await injected(*ctx.args, **ctx.kwargs)  # type: ignore
  File "c:\Users\isaac\AppData\Local\Programs\Python\Python310\lib\site-packages\discord\ext\commands\core.py", line 244, in wrapped
    raise CommandInvokeError(exc) from exc
discord.ext.commands.errors.CommandInvokeError: Command raised an exception: DownloadError: [0;31mERROR:[0m Postprocessing: ffprobe and ffmpeg not found. Please install or provide the path using --ffmpeg-location
2024-03-13 18:38:34 - INFO - Disconnecting from voice normally, close code 1000.
2024-03-13 18:38:34 - INFO - The voice handshake is being terminated for Channel ID 781272457826009150 (Guild ID 781272457394913340)
2024-03-13 18:39:45 - INFO - Disconnecting from voice normally, close code 1000.
2024-03-13 18:39:45 - INFO - The voice handshake is being terminated for Channel ID 1046467680003174443 (Guild ID 1046467676215726172)
2024-03-13 18:41:13 - INFO - logging in using static token
2024-03-13 18:41:13 - INFO - Shard ID None has connected to Gateway (Session ID: 8a693e13bdfffe6313ce93c3c8508713).
2024-03-13 18:41:15 - INFO - Bot has started and is ready.
2024-03-13 18:41:26 - INFO - Connecting to voice...
2024-03-13 18:41:26 - INFO - Starting voice handshake... (connection attempt 1)
2024-03-13 18:41:26 - INFO - Voice handshake complete. Endpoint found us-central9709.discord.media
2024-03-13 18:41:39 - ERROR - Ignoring exception in command play
Traceback (most recent call last):
  File "c:\Users\isaac\AppData\Local\Programs\Python\Python310\lib\site-packages\discord\ext\commands\core.py", line 235, in wrapped
    ret = await coro(*args, **kwargs)
  File "c:\Users\isaac\Documents\My Projects\SeShack\myBot.py", line 419, in play
    player = await YTDLSource.from_url(url, loop=bot.loop)
  File "c:\Users\isaac\Documents\My Projects\SeShack\myBot.py", line 118, in from_url
    return cls(discord.FFmpegPCMAudio(filename, **ffmpeg_options), data=data)
  File "c:\Users\isaac\AppData\Local\Programs\Python\Python310\lib\site-packages\discord\player.py", line 290, in __init__
    super().__init__(source, executable=executable, args=args, **subprocess_kwargs)
  File "c:\Users\isaac\AppData\Local\Programs\Python\Python310\lib\site-packages\discord\player.py", line 166, in __init__
    self._process = self._spawn_process(args, **kwargs)
  File "c:\Users\isaac\AppData\Local\Programs\Python\Python310\lib\site-packages\discord\player.py", line 183, in _spawn_process
    raise ClientException(executable + ' was not found.') from None
discord.errors.ClientException: ffmpeg was not found.

The above exception was the direct cause of the following exception:

Traceback (most recent call last):
  File "c:\Users\isaac\AppData\Local\Programs\Python\Python310\lib\site-packages\discord\ext\commands\bot.py", line 1350, in invoke
    await ctx.command.invoke(ctx)
  File "c:\Users\isaac\AppData\Local\Programs\Python\Python310\lib\site-packages\discord\ext\commands\core.py", line 1029, in invoke
    await injected(*ctx.args, **ctx.kwargs)  # type: ignore
  File "c:\Users\isaac\AppData\Local\Programs\Python\Python310\lib\site-packages\discord\ext\commands\core.py", line 244, in wrapped
    raise CommandInvokeError(exc) from exc
discord.ext.commands.errors.CommandInvokeError: Command raised an exception: ClientException: ffmpeg was not found.
2024-03-13 18:49:48 - ERROR - Ignoring exception in command play
Traceback (most recent call last):
  File "c:\Users\isaac\AppData\Local\Programs\Python\Python310\lib\site-packages\discord\ext\commands\core.py", line 235, in wrapped
    ret = await coro(*args, **kwargs)
  File "c:\Users\isaac\Documents\My Projects\SeShack\myBot.py", line 419, in play
    player = await YTDLSource.from_url(url, loop=bot.loop)
  File "c:\Users\isaac\Documents\My Projects\SeShack\myBot.py", line 118, in from_url
    return cls(discord.FFmpegPCMAudio(filename, **ffmpeg_options), data=data)
  File "c:\Users\isaac\AppData\Local\Programs\Python\Python310\lib\site-packages\discord\player.py", line 290, in __init__
    super().__init__(source, executable=executable, args=args, **subprocess_kwargs)
  File "c:\Users\isaac\AppData\Local\Programs\Python\Python310\lib\site-packages\discord\player.py", line 166, in __init__
    self._process = self._spawn_process(args, **kwargs)
  File "c:\Users\isaac\AppData\Local\Programs\Python\Python310\lib\site-packages\discord\player.py", line 183, in _spawn_process
    raise ClientException(executable + ' was not found.') from None
discord.errors.ClientException: ffmpeg was not found.

The above exception was the direct cause of the following exception:

Traceback (most recent call last):
  File "c:\Users\isaac\AppData\Local\Programs\Python\Python310\lib\site-packages\discord\ext\commands\bot.py", line 1350, in invoke
    await ctx.command.invoke(ctx)
  File "c:\Users\isaac\AppData\Local\Programs\Python\Python310\lib\site-packages\discord\ext\commands\core.py", line 1029, in invoke
    await injected(*ctx.args, **ctx.kwargs)  # type: ignore
  File "c:\Users\isaac\AppData\Local\Programs\Python\Python310\lib\site-packages\discord\ext\commands\core.py", line 244, in wrapped
    raise CommandInvokeError(exc) from exc
discord.ext.commands.errors.CommandInvokeError: Command raised an exception: ClientException: ffmpeg was not found.
2024-03-13 18:49:55 - INFO - logging in using static token
2024-03-13 18:49:56 - INFO - Shard ID None has connected to Gateway (Session ID: d66bdfaf0ea33bb9346183e0613c4652).
2024-03-13 18:49:58 - INFO - Bot has started and is ready.
2024-03-13 18:50:06 - ERROR - Ignoring exception in command play
Traceback (most recent call last):
  File "c:\Users\isaac\AppData\Local\Programs\Python\Python310\lib\site-packages\discord\ext\commands\core.py", line 235, in wrapped
    ret = await coro(*args, **kwargs)
  File "c:\Users\isaac\Documents\My Projects\SeShack\myBot.py", line 419, in play
    player = await YTDLSource.from_url(url, loop=bot.loop)
  File "c:\Users\isaac\Documents\My Projects\SeShack\myBot.py", line 118, in from_url
    return cls(discord.FFmpegPCMAudio(filename, **ffmpeg_options), data=data)
  File "c:\Users\isaac\AppData\Local\Programs\Python\Python310\lib\site-packages\discord\player.py", line 290, in __init__
    super().__init__(source, executable=executable, args=args, **subprocess_kwargs)
  File "c:\Users\isaac\AppData\Local\Programs\Python\Python310\lib\site-packages\discord\player.py", line 166, in __init__
    self._process = self._spawn_process(args, **kwargs)
  File "c:\Users\isaac\AppData\Local\Programs\Python\Python310\lib\site-packages\discord\player.py", line 183, in _spawn_process
    raise ClientException(executable + ' was not found.') from None
discord.errors.ClientException: ffmpeg was not found.

The above exception was the direct cause of the following exception:

Traceback (most recent call last):
  File "c:\Users\isaac\AppData\Local\Programs\Python\Python310\lib\site-packages\discord\ext\commands\bot.py", line 1350, in invoke
    await ctx.command.invoke(ctx)
  File "c:\Users\isaac\AppData\Local\Programs\Python\Python310\lib\site-packages\discord\ext\commands\core.py", line 1029, in invoke
    await injected(*ctx.args, **ctx.kwargs)  # type: ignore
  File "c:\Users\isaac\AppData\Local\Programs\Python\Python310\lib\site-packages\discord\ext\commands\core.py", line 244, in wrapped
    raise CommandInvokeError(exc) from exc
discord.ext.commands.errors.CommandInvokeError: Command raised an exception: ClientException: ffmpeg was not found.
2024-03-13 18:51:22 - INFO - logging in using static token
2024-03-13 18:51:23 - INFO - Shard ID None has connected to Gateway (Session ID: 3ad35d101d9295d5a4ba3975340cebf8).
2024-03-13 18:51:25 - INFO - Bot has started and is ready.
2024-03-13 18:51:25 - INFO - Connecting to voice...
2024-03-13 18:51:25 - INFO - Starting voice handshake... (connection attempt 1)
2024-03-13 18:51:25 - INFO - Voice handshake complete. Endpoint found us-central9709.discord.media
2024-03-13 18:52:01 - INFO - ffmpeg process 123136 successfully terminated with return code of 0.
2024-03-13 18:52:02 - INFO - Disconnecting from voice normally, close code 1000.
2024-03-13 18:52:02 - INFO - The voice handshake is being terminated for Channel ID 1046467680003174443 (Guild ID 1046467676215726172)
2024-03-13 18:52:15 - INFO - Connecting to voice...
2024-03-13 18:52:15 - INFO - Starting voice handshake... (connection attempt 1)
2024-03-13 18:52:15 - INFO - Voice handshake complete. Endpoint found us-central7530.discord.media
2024-03-13 18:52:52 - INFO - ffmpeg process 43704 successfully terminated with return code of 0.
2024-03-13 18:53:26 - INFO - Disconnecting from voice normally, close code 1000.
2024-03-13 18:53:26 - INFO - The voice handshake is being terminated for Channel ID 781272457826009150 (Guild ID 781272457394913340)
2024-03-13 18:55:07 - INFO - logging in using static token
2024-03-13 18:55:08 - INFO - Shard ID None has connected to Gateway (Session ID: e6bf69168d4e77576a624d1a7246bbab).
2024-03-13 18:55:10 - INFO - Bot has started and is ready.
2024-03-13 18:56:41 - INFO - logging in using static token
2024-03-13 18:56:41 - INFO - Shard ID None has connected to Gateway (Session ID: 3886c6f10e7cc0ac25efc6167040e652).
2024-03-13 18:56:43 - INFO - Bot has started and is ready.
2024-03-13 18:57:15 - INFO - Connecting to voice...
2024-03-13 18:57:15 - INFO - Starting voice handshake... (connection attempt 1)
2024-03-13 18:57:15 - INFO - Voice handshake complete. Endpoint found us-central2720.discord.media
2024-03-13 18:57:28 - ERROR - Ignoring exception in command play
Traceback (most recent call last):
  File "c:\Users\isaac\AppData\Local\Programs\Python\Python310\lib\site-packages\discord\ext\commands\core.py", line 235, in wrapped
    ret = await coro(*args, **kwargs)
  File "c:\Users\isaac\Documents\My Projects\SeShack\myBot.py", line 438, in play
    ctx.voice_client.play(player, after=lambda e: print(f'Player error: {e}') if e else None)
  File "c:\Users\isaac\AppData\Local\Programs\Python\Python310\lib\site-packages\discord\voice_client.py", line 608, in play
    raise ClientException('Already playing audio.')
discord.errors.ClientException: Already playing audio.

The above exception was the direct cause of the following exception:

Traceback (most recent call last):
  File "c:\Users\isaac\AppData\Local\Programs\Python\Python310\lib\site-packages\discord\ext\commands\bot.py", line 1350, in invoke
    await ctx.command.invoke(ctx)
  File "c:\Users\isaac\AppData\Local\Programs\Python\Python310\lib\site-packages\discord\ext\commands\core.py", line 1029, in invoke
    await injected(*ctx.args, **ctx.kwargs)  # type: ignore
  File "c:\Users\isaac\AppData\Local\Programs\Python\Python310\lib\site-packages\discord\ext\commands\core.py", line 244, in wrapped
    raise CommandInvokeError(exc) from exc
discord.ext.commands.errors.CommandInvokeError: Command raised an exception: ClientException: Already playing audio.
2024-03-13 18:57:28 - INFO - ffmpeg process 126852 has not terminated. Waiting to terminate...
2024-03-13 18:57:28 - INFO - ffmpeg process 126852 should have terminated with a return code of 1.
2024-03-13 18:57:45 - INFO - Disconnecting from voice normally, close code 1000.
2024-03-13 18:57:45 - INFO - ffmpeg process 125992 has not terminated. Waiting to terminate...
2024-03-13 18:57:45 - INFO - ffmpeg process 125992 should have terminated with a return code of 1.
2024-03-13 18:57:45 - INFO - The voice handshake is being terminated for Channel ID 781272457826009150 (Guild ID 781272457394913340)
2024-03-13 18:59:18 - INFO - logging in using static token
2024-03-13 18:59:19 - INFO - Shard ID None has connected to Gateway (Session ID: 0c3a620ff933cd99819834a2af7cf83e).
2024-03-13 18:59:21 - INFO - Bot has started and is ready.
2024-03-13 19:00:34 - INFO - logging in using static token
2024-03-13 19:00:35 - INFO - Shard ID None has connected to Gateway (Session ID: fe1cbd8ec7552cf6a06f95ca10b40e82).
2024-03-13 19:00:37 - INFO - Bot has started and is ready.
2024-03-13 19:02:36 - INFO - logging in using static token
2024-03-13 19:02:37 - INFO - Shard ID None has connected to Gateway (Session ID: 74fbc6dc8c7d568277245dedf69ab2f6).
2024-03-13 19:02:39 - INFO - Bot has started and is ready.
2024-03-13 19:02:45 - INFO - 8Ball used by itzkagyu, question: 'balls' - response: 'Outlook good.'.
2024-03-13 19:03:20 - INFO - logging in using static token
2024-03-13 19:03:21 - INFO - Shard ID None has connected to Gateway (Session ID: ae18a6baa24f8edc98d4d744b310861b).
2024-03-13 19:03:23 - INFO - Bot has started and is ready.
2024-03-13 19:03:29 - INFO - logging in using static token
2024-03-13 19:03:30 - INFO - Shard ID None has connected to Gateway (Session ID: b07976b51242d9b97b7cc890b40ac392).
2024-03-13 19:03:32 - INFO - Bot has started and is ready.
2024-03-13 19:03:37 - INFO - 8Ball used by itzkagyu, question: 'balls' - response: 'My sources say no.'.
2024-03-13 19:04:20 - INFO - logging in using static token
2024-03-13 19:04:21 - INFO - Shard ID None has connected to Gateway (Session ID: 09b21f0c7e3501c3b194d607486510d8).
2024-03-13 19:04:23 - INFO - Bot has started and is ready.
2024-03-13 19:04:43 - INFO - logging in using static token
2024-03-13 19:04:44 - INFO - Shard ID None has connected to Gateway (Session ID: c25662be667768f3c300e7d07f6d7af7).
2024-03-13 19:04:46 - INFO - Bot has started and is ready.
2024-03-13 19:04:52 - INFO - 8Ball used by itzkagyu, question: 'balls' - response: 'Nuh uh.'.
